[2019-03-18 22:47:23,126] {/home/alphatech/.local/lib/python3.6/site-packages/flask/app.py:1761} ERROR - Exception on /cart [POST]
Traceback (most recent call last):
  File "/home/alphatech/.local/lib/python3.6/site-packages/sqlalchemy/engine/base.py", line 1244, in _execute_context
    cursor, statement, parameters, context
  File "/home/alphatech/.local/lib/python3.6/site-packages/sqlalchemy/engine/default.py", line 552, in do_execute
    cursor.execute(statement, parameters)
  File "/home/alphatech/.local/lib/python3.6/site-packages/pymysql/cursors.py", line 170, in execute
    result = self._query(query)
  File "/home/alphatech/.local/lib/python3.6/site-packages/pymysql/cursors.py", line 328, in _query
    conn.query(q)
  File "/home/alphatech/.local/lib/python3.6/site-packages/pymysql/connections.py", line 517, in query
    self._affected_rows = self._read_query_result(unbuffered=unbuffered)
  File "/home/alphatech/.local/lib/python3.6/site-packages/pymysql/connections.py", line 732, in _read_query_result
    result.read()
  File "/home/alphatech/.local/lib/python3.6/site-packages/pymysql/connections.py", line 1075, in read
    first_packet = self.connection._read_packet()
  File "/home/alphatech/.local/lib/python3.6/site-packages/pymysql/connections.py", line 684, in _read_packet
    packet.check_error()
  File "/home/alphatech/.local/lib/python3.6/site-packages/pymysql/protocol.py", line 220, in check_error
    err.raise_mysql_exception(self._data)
  File "/home/alphatech/.local/lib/python3.6/site-packages/pymysql/err.py", line 109, in raise_mysql_exception
    raise errorclass(errno, errval)
pymysql.err.IntegrityError: (1062, "Duplicate entry '78947' for key 'PRIMARY'")

The above exception was the direct cause of the following exception:

Traceback (most recent call last):
  File "/home/alphatech/.local/lib/python3.6/site-packages/flask/app.py", line 1813, in full_dispatch_request
    rv = self.dispatch_request()
  File "/home/alphatech/.local/lib/python3.6/site-packages/flask/app.py", line 1799, in dispatch_request
    return self.view_functions[rule.endpoint](**req.view_args)
  File "/home/alphatech/.local/lib/python3.6/site-packages/flask_restful/__init__.py", line 458, in wrapper
    resp = resource(*args, **kwargs)
  File "/home/alphatech/.local/lib/python3.6/site-packages/flask/views.py", line 88, in view
    return self.dispatch_request(*args, **kwargs)
  File "/home/alphatech/.local/lib/python3.6/site-packages/flask_restful/__init__.py", line 573, in dispatch_request
    resp = meth(*args, **kwargs)
  File "/home/alphatech/.local/lib/python3.6/site-packages/flask_jwt_extended/view_decorators.py", line 104, in wrapper
    return fn(*args, **kwargs)
  File "/home/alphatech/Documents/BIG/Fase awal/env_eCommerce/eCommerce/blueprints/cart/resources.py", line 92, in post
    db.session.commit()
  File "/home/alphatech/.local/lib/python3.6/site-packages/sqlalchemy/orm/scoping.py", line 162, in do
    return getattr(self.registry(), name)(*args, **kwargs)
  File "/home/alphatech/.local/lib/python3.6/site-packages/sqlalchemy/orm/session.py", line 1026, in commit
    self.transaction.commit()
  File "/home/alphatech/.local/lib/python3.6/site-packages/sqlalchemy/orm/session.py", line 493, in commit
    self._prepare_impl()
  File "/home/alphatech/.local/lib/python3.6/site-packages/sqlalchemy/orm/session.py", line 472, in _prepare_impl
    self.session.flush()
  File "/home/alphatech/.local/lib/python3.6/site-packages/sqlalchemy/orm/session.py", line 2451, in flush
    self._flush(objects)
  File "/home/alphatech/.local/lib/python3.6/site-packages/sqlalchemy/orm/session.py", line 2589, in _flush
    transaction.rollback(_capture_exception=True)
  File "/home/alphatech/.local/lib/python3.6/site-packages/sqlalchemy/util/langhelpers.py", line 68, in __exit__
    compat.reraise(exc_type, exc_value, exc_tb)
  File "/home/alphatech/.local/lib/python3.6/site-packages/sqlalchemy/util/compat.py", line 129, in reraise
    raise value
  File "/home/alphatech/.local/lib/python3.6/site-packages/sqlalchemy/orm/session.py", line 2549, in _flush
    flush_context.execute()
  File "/home/alphatech/.local/lib/python3.6/site-packages/sqlalchemy/orm/unitofwork.py", line 422, in execute
    rec.execute(self)
  File "/home/alphatech/.local/lib/python3.6/site-packages/sqlalchemy/orm/unitofwork.py", line 589, in execute
    uow,
  File "/home/alphatech/.local/lib/python3.6/site-packages/sqlalchemy/orm/persistence.py", line 245, in save_obj
    insert,
  File "/home/alphatech/.local/lib/python3.6/site-packages/sqlalchemy/orm/persistence.py", line 1066, in _emit_insert_statements
    c = cached_connections[connection].execute(statement, multiparams)
  File "/home/alphatech/.local/lib/python3.6/site-packages/sqlalchemy/engine/base.py", line 988, in execute
    return meth(self, multiparams, params)
  File "/home/alphatech/.local/lib/python3.6/site-packages/sqlalchemy/sql/elements.py", line 287, in _execute_on_connection
    return connection._execute_clauseelement(self, multiparams, params)
  File "/home/alphatech/.local/lib/python3.6/site-packages/sqlalchemy/engine/base.py", line 1107, in _execute_clauseelement
    distilled_params,
  File "/home/alphatech/.local/lib/python3.6/site-packages/sqlalchemy/engine/base.py", line 1248, in _execute_context
    e, statement, parameters, cursor, context
  File "/home/alphatech/.local/lib/python3.6/site-packages/sqlalchemy/engine/base.py", line 1466, in _handle_dbapi_exception
    util.raise_from_cause(sqlalchemy_exception, exc_info)
  File "/home/alphatech/.local/lib/python3.6/site-packages/sqlalchemy/util/compat.py", line 383, in raise_from_cause
    reraise(type(exception), exception, tb=exc_tb, cause=cause)
  File "/home/alphatech/.local/lib/python3.6/site-packages/sqlalchemy/util/compat.py", line 128, in reraise
    raise value.with_traceback(tb)
  File "/home/alphatech/.local/lib/python3.6/site-packages/sqlalchemy/engine/base.py", line 1244, in _execute_context
    cursor, statement, parameters, context
  File "/home/alphatech/.local/lib/python3.6/site-packages/sqlalchemy/engine/default.py", line 552, in do_execute
    cursor.execute(statement, parameters)
  File "/home/alphatech/.local/lib/python3.6/site-packages/pymysql/cursors.py", line 170, in execute
    result = self._query(query)
  File "/home/alphatech/.local/lib/python3.6/site-packages/pymysql/cursors.py", line 328, in _query
    conn.query(q)
  File "/home/alphatech/.local/lib/python3.6/site-packages/pymysql/connections.py", line 517, in query
    self._affected_rows = self._read_query_result(unbuffered=unbuffered)
  File "/home/alphatech/.local/lib/python3.6/site-packages/pymysql/connections.py", line 732, in _read_query_result
    result.read()
  File "/home/alphatech/.local/lib/python3.6/site-packages/pymysql/connections.py", line 1075, in read
    first_packet = self.connection._read_packet()
  File "/home/alphatech/.local/lib/python3.6/site-packages/pymysql/connections.py", line 684, in _read_packet
    packet.check_error()
  File "/home/alphatech/.local/lib/python3.6/site-packages/pymysql/protocol.py", line 220, in check_error
    err.raise_mysql_exception(self._data)
  File "/home/alphatech/.local/lib/python3.6/site-packages/pymysql/err.py", line 109, in raise_mysql_exception
    raise errorclass(errno, errval)
sqlalchemy.exc.IntegrityError: (pymysql.err.IntegrityError) (1062, "Duplicate entry '78947' for key 'PRIMARY'")
[SQL: INSERT INTO cart (resi, user_pembeli, barang, deskripsi, jenis, harga, status, jumlah) VALUES (%(resi)s, %(user_pembeli)s, %(barang)s, %(deskripsi)s, %(jenis)s, %(harga)s, %(status)s, %(jumlah)s)]
[parameters: {'resi': 78947, 'user_pembeli': 'danu', 'barang': 'juggernaut clothes', 'deskripsi': 'Barang mulus, 90% original', 'jenis': 'mainan', 'harga': 60000, 'status': 'Available', 'jumlah': 3}]
(Background on this error at: http://sqlalche.me/e/gkpj)
[2019-03-18 22:59:53,533] {/home/alphatech/.local/lib/python3.6/site-packages/flask/app.py:1761} ERROR - Exception on /cart [DELETE]
Traceback (most recent call last):
  File "/home/alphatech/.local/lib/python3.6/site-packages/flask/app.py", line 1813, in full_dispatch_request
    rv = self.dispatch_request()
  File "/home/alphatech/.local/lib/python3.6/site-packages/flask/app.py", line 1799, in dispatch_request
    return self.view_functions[rule.endpoint](**req.view_args)
  File "/home/alphatech/.local/lib/python3.6/site-packages/flask_restful/__init__.py", line 458, in wrapper
    resp = resource(*args, **kwargs)
  File "/home/alphatech/.local/lib/python3.6/site-packages/flask/views.py", line 88, in view
    return self.dispatch_request(*args, **kwargs)
  File "/home/alphatech/.local/lib/python3.6/site-packages/flask_restful/__init__.py", line 573, in dispatch_request
    resp = meth(*args, **kwargs)
  File "/home/alphatech/.local/lib/python3.6/site-packages/flask_jwt_extended/view_decorators.py", line 104, in wrapper
    return fn(*args, **kwargs)
  File "/home/alphatech/Documents/BIG/Fase awal/env_eCommerce/eCommerce/blueprints/cart/resources.py", line 168, in delete
    barang = Barangs.query.get(args['resi'])
AttributeError: 'NoneType' object has no attribute 'user_pembeli'
